[2024-09-04 10:46:27,470] INFO _log() L224   * Restarting with stat - call_trace=/home/cyberforming-1790/.local/lib/python3.10/site-packages/werkzeug/_internal.py L224 
[2024-09-04 10:46:28,480] WARNING get_patient() L140  Error searching for patient 'Paula', Patient Paula not found in the database :/ - call_trace=/home/cyberforming-1790/Documentos/mvp_sprint2/api/app.py L140 
[2024-09-04 10:46:28,481] INFO _log() L224  127.0.0.1 - - [04/Sep/2024 10:46:28] "[33mGET /patient?name=Paula HTTP/1.1[0m" 404 - - call_trace=/home/cyberforming-1790/.local/lib/python3.10/site-packages/werkzeug/_internal.py L224 
[2024-09-04 10:46:29,357] WARNING get_patient() L140  Error searching for patient 'Paula', Patient Paula not found in the database :/ - call_trace=/home/cyberforming-1790/Documentos/mvp_sprint2/api/app.py L140 
[2024-09-04 10:46:29,358] INFO _log() L224  127.0.0.1 - - [04/Sep/2024 10:46:29] "[33mGET /patient?name=Paula HTTP/1.1[0m" 404 - - call_trace=/home/cyberforming-1790/.local/lib/python3.10/site-packages/werkzeug/_internal.py L224 
[2024-09-04 10:46:30,185] WARNING get_patient() L140  Error searching for patient 'Paula', Patient Paula not found in the database :/ - call_trace=/home/cyberforming-1790/Documentos/mvp_sprint2/api/app.py L140 
[2024-09-04 10:46:30,185] INFO _log() L224  127.0.0.1 - - [04/Sep/2024 10:46:30] "[33mGET /patient?name=Paula HTTP/1.1[0m" 404 - - call_trace=/home/cyberforming-1790/.local/lib/python3.10/site-packages/werkzeug/_internal.py L224 
[2024-09-04 10:46:31,148] WARNING get_patient() L140  Error searching for patient 'Paula', Patient Paula not found in the database :/ - call_trace=/home/cyberforming-1790/Documentos/mvp_sprint2/api/app.py L140 
[2024-09-04 10:46:31,149] INFO _log() L224  127.0.0.1 - - [04/Sep/2024 10:46:31] "[33mGET /patient?name=Paula HTTP/1.1[0m" 404 - - call_trace=/home/cyberforming-1790/.local/lib/python3.10/site-packages/werkzeug/_internal.py L224 
[2024-09-04 10:47:20,972] INFO _log() L224  127.0.0.1 - - [04/Sep/2024 10:47:20] "GET /openapi/swagger HTTP/1.1" 200 - - call_trace=/home/cyberforming-1790/.local/lib/python3.10/site-packages/werkzeug/_internal.py L224 
[2024-09-04 10:47:21,030] INFO _log() L224  127.0.0.1 - - [04/Sep/2024 10:47:21] "[36mGET /openapi/static/css/swagger-ui.css HTTP/1.1[0m" 304 - - call_trace=/home/cyberforming-1790/.local/lib/python3.10/site-packages/werkzeug/_internal.py L224 
[2024-09-04 10:47:21,034] INFO _log() L224  127.0.0.1 - - [04/Sep/2024 10:47:21] "[36mGET /openapi/static/js/swagger-ui-standalone-preset.js HTTP/1.1[0m" 304 - - call_trace=/home/cyberforming-1790/.local/lib/python3.10/site-packages/werkzeug/_internal.py L224 
[2024-09-04 10:47:21,035] INFO _log() L224  127.0.0.1 - - [04/Sep/2024 10:47:21] "[36mGET /openapi/static/js/swagger-ui-bundle.js HTTP/1.1[0m" 304 - - call_trace=/home/cyberforming-1790/.local/lib/python3.10/site-packages/werkzeug/_internal.py L224 
[2024-09-04 10:47:21,288] INFO _log() L224  127.0.0.1 - - [04/Sep/2024 10:47:21] "GET /openapi/openapi.json HTTP/1.1" 200 - - call_trace=/home/cyberforming-1790/.local/lib/python3.10/site-packages/werkzeug/_internal.py L224 
[2024-09-04 10:47:21,300] INFO _log() L224  127.0.0.1 - - [04/Sep/2024 10:47:21] "[36mGET /openapi/static/images/swagger.svg HTTP/1.1[0m" 304 - - call_trace=/home/cyberforming-1790/.local/lib/python3.10/site-packages/werkzeug/_internal.py L224 
[2024-09-04 10:47:21,757] INFO _log() L224   * Detected change in '/home/cyberforming-1790/Documentos/mvp_sprint2/api/app.py', reloading - call_trace=/home/cyberforming-1790/.local/lib/python3.10/site-packages/werkzeug/_internal.py L224 
[2024-09-04 10:47:22,025] INFO _log() L224   * Restarting with stat - call_trace=/home/cyberforming-1790/.local/lib/python3.10/site-packages/werkzeug/_internal.py L224 
[2024-09-04 10:47:29,821] INFO _log() L224  127.0.0.1 - - [04/Sep/2024 10:47:29] "POST /patient HTTP/1.1" 200 - - call_trace=/home/cyberforming-1790/.local/lib/python3.10/site-packages/werkzeug/_internal.py L224 
[2024-09-04 10:47:39,787] INFO _log() L224  127.0.0.1 - - [04/Sep/2024 10:47:39] "GET /patient?name=Paula HTTP/1.1" 200 - - call_trace=/home/cyberforming-1790/.local/lib/python3.10/site-packages/werkzeug/_internal.py L224 
[2024-09-04 10:48:00,583] ERROR log_exception() L1449 Exception on /patients [GET] - call_trace=/home/cyberforming-1790/.local/lib/python3.10/site-packages/flask/app.py L1449
Traceback (most recent call last):
  File "/home/cyberforming-1790/.local/lib/python3.10/site-packages/flask/app.py", line 2073, in wsgi_app
    response = self.full_dispatch_request()
  File "/home/cyberforming-1790/.local/lib/python3.10/site-packages/flask/app.py", line 1519, in full_dispatch_request
    rv = self.handle_user_exception(e)
  File "/home/cyberforming-1790/.local/lib/python3.10/site-packages/flask_cors/extension.py", line 165, in wrapped_function
    return cors_after_request(app.make_response(f(*args, **kwargs)))
  File "/home/cyberforming-1790/.local/lib/python3.10/site-packages/flask/app.py", line 1517, in full_dispatch_request
    rv = self.dispatch_request()
  File "/home/cyberforming-1790/.local/lib/python3.10/site-packages/flask/app.py", line 1503, in dispatch_request
    return self.ensure_sync(self.view_functions[rule.endpoint])(**req.view_args)
  File "/home/cyberforming-1790/.local/lib/python3.10/site-packages/flask_openapi3/scaffold.py", line 109, in wrapper
    resp = _do_wrapper(
  File "/home/cyberforming-1790/.local/lib/python3.10/site-packages/flask_openapi3/do_wrapper.py", line 135, in _do_wrapper
    response = func(**request_kwargs)
  File "/home/cyberforming-1790/Documentos/mvp_sprint2/api/app.py", line 51, in get_patients
    return represent_patient(patients), 200
  File "/home/cyberforming-1790/Documentos/mvp_sprint2/api/schemas/patient_schema.py", line 45, in represent_patient
    "id": patient.id,
AttributeError: 'list' object has no attribute 'id'
[2024-09-04 10:48:00,593] INFO _log() L224  127.0.0.1 - - [04/Sep/2024 10:48:00] "[35m[1mGET /patients HTTP/1.1[0m" 500 - - call_trace=/home/cyberforming-1790/.local/lib/python3.10/site-packages/werkzeug/_internal.py L224 
[2024-09-04 10:49:21,748] INFO _log() L224   * Detected change in '/home/cyberforming-1790/Documentos/mvp_sprint2/api/asdad.py', reloading - call_trace=/home/cyberforming-1790/.local/lib/python3.10/site-packages/werkzeug/_internal.py L224 
[2024-09-04 10:49:21,970] INFO _log() L224   * Restarting with stat - call_trace=/home/cyberforming-1790/.local/lib/python3.10/site-packages/werkzeug/_internal.py L224 
[2024-09-04 10:50:07,084] INFO _log() L224   * Detected change in '/home/cyberforming-1790/Documentos/mvp_sprint2/api/app.py', reloading - call_trace=/home/cyberforming-1790/.local/lib/python3.10/site-packages/werkzeug/_internal.py L224 
[2024-09-04 10:50:07,269] INFO _log() L224   * Restarting with stat - call_trace=/home/cyberforming-1790/.local/lib/python3.10/site-packages/werkzeug/_internal.py L224 
[2024-09-04 10:50:31,310] INFO _log() L224   * Detected change in '/home/cyberforming-1790/Documentos/mvp_sprint2/api/app.py', reloading - call_trace=/home/cyberforming-1790/.local/lib/python3.10/site-packages/werkzeug/_internal.py L224 
[2024-09-04 10:50:31,467] INFO _log() L224   * Restarting with stat - call_trace=/home/cyberforming-1790/.local/lib/python3.10/site-packages/werkzeug/_internal.py L224 
[2024-09-04 10:50:35,702] ERROR log_exception() L1449 Exception on /patients [GET] - call_trace=/home/cyberforming-1790/.local/lib/python3.10/site-packages/flask/app.py L1449
Traceback (most recent call last):
  File "/home/cyberforming-1790/.local/lib/python3.10/site-packages/flask/app.py", line 2073, in wsgi_app
    response = self.full_dispatch_request()
  File "/home/cyberforming-1790/.local/lib/python3.10/site-packages/flask/app.py", line 1519, in full_dispatch_request
    rv = self.handle_user_exception(e)
  File "/home/cyberforming-1790/.local/lib/python3.10/site-packages/flask_cors/extension.py", line 165, in wrapped_function
    return cors_after_request(app.make_response(f(*args, **kwargs)))
  File "/home/cyberforming-1790/.local/lib/python3.10/site-packages/flask/app.py", line 1517, in full_dispatch_request
    rv = self.dispatch_request()
  File "/home/cyberforming-1790/.local/lib/python3.10/site-packages/flask/app.py", line 1503, in dispatch_request
    return self.ensure_sync(self.view_functions[rule.endpoint])(**req.view_args)
  File "/home/cyberforming-1790/.local/lib/python3.10/site-packages/flask_openapi3/scaffold.py", line 109, in wrapper
    resp = _do_wrapper(
  File "/home/cyberforming-1790/.local/lib/python3.10/site-packages/flask_openapi3/do_wrapper.py", line 135, in _do_wrapper
    response = func(**request_kwargs)
  File "/home/cyberforming-1790/Documentos/mvp_sprint2/api/app.py", line 51, in get_patients
    return represent_patient(patients), 200
  File "/home/cyberforming-1790/Documentos/mvp_sprint2/api/schemas/patient_schema.py", line 45, in represent_patient
    "id": patient.id,
AttributeError: 'list' object has no attribute 'id'
[2024-09-04 10:50:35,704] INFO _log() L224  127.0.0.1 - - [04/Sep/2024 10:50:35] "[35m[1mGET /patients HTTP/1.1[0m" 500 - - call_trace=/home/cyberforming-1790/.local/lib/python3.10/site-packages/werkzeug/_internal.py L224 
[2024-09-04 10:54:00,016] INFO _log() L224   * Restarting with stat - call_trace=/home/cyberforming-1790/.local/lib/python3.10/site-packages/werkzeug/_internal.py L224 
[2024-09-04 11:29:44,171] INFO _log() L224   * Restarting with stat - call_trace=/home/cyberforming-1790/.local/lib/python3.10/site-packages/werkzeug/_internal.py L224 
